Workbook

Sheet DB-GPT_detailed
B2: Cẩm Nang Triển Khai DB-GPT Toàn Diện (A-to-Z) | F2: Cẩm Nang DB-GPT
B3: Phiên bản: v0.7+ | Tiêu điểm: Dynamic (Local + Cloud), Bảo mật, Đa năng | K3: Cloud Service
K4: User → Application → API Gateway/Proxy → Cloud LLM Service → Response
B5: 1. Kiến trúc | K5: (OpenAI, Claude, etc)
B6: Trước khi cài đặt, hãy hiểu bạn đang xây dựng cái gì. DB-GPT không chỉ là một chatbot, nó là một Hệ Điều Hành Dữ Liệu (Data Operating System). | K6: Cần internet connection
K7: Latency cao hơn (network overhead)
B8: Người Quản Lý (The Manager - DB-GPT): Là phần mềm trung tâm. Nó không biết suy nghĩ, nhưng nó nắm giữ "trí nhớ ngắn hạn" (Lịch sử chat) và "thư viện tài liệu" (Vector Store). | K8: Không kiểm soát được model
B9: Bộ Não (The Brain - Proxy LLM): Nơi xử lý thông tin. Bạn có thể dùng Hybrid Strategy: | K9: Chi phí theo usage (token-based)
B10: Local: Ollama, vLLM (Riêng tư tuyệt đối). | K10: Không lo về infrastructure
B11: Cloud: OpenAI, DeepSeek, Claude (Thông minh nhất). | K11: Localhost với các model được pull
B12: Trí Nhớ (The Memory - Vector Store): Nơi lưu trữ tài liệu PDF/Word dưới dạng số học (Embeddings). Chúng ta dùng ChromaDB. | K12: User → Application → Ollama Client → Ollama Server → LLM Model → Response
B13: Dữ Liệu (The Data - SQL & Excel): Cơ sở dữ liệu kinh doanh (PostgreSQL, MySQL) và file Excel. | K13: (localhost:11434) (RAM/VRAM)
B14: Cánh Tay (The Hands - Tools/Plugins): Khả năng gọi API bên ngoài (Custom API, MCP).
B15: Họa Sĩ (The Visualizer - Text2Vis): Khả năng vẽ biểu đồ từ dữ liệu. | K15: Chạy hoàn toàn offline
K16: Ollama handle model management (download, load, unload)
B17: 2. Cài Đặt | K17: API đơn giản, giống OpenAI format
B18: Chuẩn bị (Prerequisites) | K18: Hỗ trợ nhiều model formats (GGUF, GGML)
B19: Python 3.10+: Đã cài đặt. | K19: Tự động optimize cho hardware
B20: UV: Trình quản lý gói Python hiện đại. (pip install uv)
B21: Ollama: (Tùy chọn) Nếu muốn chạy Local. | K21: Cloud Service
B22: Bước A: Tải mã nguồn & Cài đặt thư viện | K22: User → Application → API Gateway/Proxy → Cloud LLM Service → Response
B23: Mở terminal và chạy lệnh sau (đã thêm driver cho OpenAI/DeepSeek và Vis): | K23: (OpenAI, Claude, etc)
K24: Cần internet connection
B25: # 1. Tải mã nguồn | K25: Latency cao hơn (network overhead)
B26: git clone [https://github.com/eosphoros-ai/DB-GPT.git](https://github.com/eosphoros-ai/DB-GPT.git) | K26: Không kiểm soát được model
B27: cd DB-GPT | K27: Chi phí theo usage (token-based)
K28: Không lo về infrastructure
B29: # 2. Lệnh cài đặt "Universal"(bash) | K29: Localhost với các model được pull
B30: # Thêm proxy_openai để hỗ trợ cả GPT-4, DeepSeek, và vLLM | K30: User → Application → Ollama Client → Ollama Server → LLM Model → Response
B31: uv sync --all-packages \ (thay \ thành ` cho powershell) | K31: (localhost:11434) (RAM/VRAM)
B32: --extra "base" \
B33: --extra "proxy_ollama" \ | K33: Chạy hoàn toàn offline
B34: --extra "proxy_openai" \ | K34: Ollama handle model management (download, load, unload)
B35: --extra "datasource_postgres" \ | K35: API đơn giản, giống OpenAI format
B36: --extra "datasource_mysql" \ | K36: Hỗ trợ nhiều model formats (GGUF, GGML)
B37: --extra "rag" \ | K37: Tự động optimize cho hardware
B38: --extra "storage_chromadb" \ | K38: tự train thêm model bằng chính data của mình dựa trên các LLM libraries
B39: --extra "dbgpts" | K39: User → Application → LLM Library → Model Files → GPU/CPU → Response
K40: (transformers, (weights)
B41: 3. Cấu Hình "Bộ Não" Linh Hoạt (Dynamic Configuration) | K41: llama.cpp, etc)
...

Sheet Prompts_Txt_to_SQL
A1: Type ID | B1: Loại Prompt | C1: Level | D1: Prompt
A2: =CONCATENATE(B2,"-",C2) -> P10-1 | B2: P10 | C2: 1 | D2: Đề xuất các chỉ số (KPI) chính để theo dõi hiệu quả bán hàng tổng thể dựa trên dataset. Chỉ liệt kê KPI, không cần biểu đồ.
A3: =CONCATENATE(B3,"-",C3) -> P10-2 | B3: P10 | C3: 2 | D3: Thiết kế một dashboard theo dõi doanh thu theo thời gian và theo sản phẩm. Nêu rõ mỗi biểu đồ dùng dữ liệu từ bảng nào và mục đích của biểu đồ.
A4: =CONCATENATE(B4,"-",C4) -> P10-3 | B4: P10 | C4: 3 | D4: Thiết kế dashboard cho quản lý chất lượng sản phẩm, kết hợp dữ liệu bán hàng và bảo hành. Nêu rõ giới hạn của dashboard do thiếu dữ liệu trong schema.

Sheet Copy of Tests_extended
A1: Base Row | B1: Version | C1: Type ID New | D1: Loại Prompt | E1: Level | F1: Type ID | G1: Prompt (Cũ) | H1: Prompt (mới)
A2: =INT((ROW()-2)/20)+2 -> 2 | B2: =TEXT(MOD(ROW()-2,20)+1,"00") -> 01 | C2: {=INDEX(Prompts_Txt_to_SQL!A:A, A2)&"-"&B2} -> P10-1-01 | D2: {=INDEX(Prompts_Txt_to_SQL!B:B, A2)} -> P10 | E2: {=INDEX(Prompts_Txt_to_SQL!C:C, A2)} -> 1 | F2: =CONCATENATE(D2,"-",E2) -> P10-1 | G2: =IFERROR(VLOOKUP(F2,Prompts_Txt_to_SQL!$A$2:$G$4,4,0),"") -> Đề xuất các chỉ số (KPI) chính để theo dõi hiệu quả bán hàng tổng thể dựa trên dataset. Chỉ liệt kê KPI, không cần biểu đồ.
A3: =INT((ROW()-2)/20)+2 -> 2 | B3: =TEXT(MOD(ROW()-2,20)+1,"00") -> 02 | C3: {=INDEX(Prompts_Txt_to_SQL!A:A, A3)&"-"&B3} -> P10-1-02 | D3: {=INDEX(Prompts_Txt_to_SQL!B:B, A3)} -> P10 | E3: {=INDEX(Prompts_Txt_to_SQL!C:C, A3)} -> 1 | F3: =CONCATENATE(D3,"-",E3) -> P10-1 | G3: =IFERROR(VLOOKUP(F3,Prompts_Txt_to_SQL!$A$2:$G$4,4,0),"") -> Đề xuất các chỉ số (KPI) chính để theo dõi hiệu quả bán hàng tổng thể dựa trên dataset. Chỉ liệt kê KPI, không cần biểu đồ.
A4: =INT((ROW()-2)/20)+2 -> 2 | B4: =TEXT(MOD(ROW()-2,20)+1,"00") -> 03 | C4: {=INDEX(Prompts_Txt_to_SQL!A:A, A4)&"-"&B4} -> P10-1-03 | D4: {=INDEX(Prompts_Txt_to_SQL!B:B, A4)} -> P10 | E4: {=INDEX(Prompts_Txt_to_SQL!C:C, A4)} -> 1 | F4: =CONCATENATE(D4,"-",E4) -> P10-1 | G4: =IFERROR(VLOOKUP(F4,Prompts_Txt_to_SQL!$A$2:$G$4,4,0),"") -> Đề xuất các chỉ số (KPI) chính để theo dõi hiệu quả bán hàng tổng thể dựa trên dataset. Chỉ liệt kê KPI, không cần biểu đồ.
A5: =INT((ROW()-2)/20)+2 -> 2 | B5: =TEXT(MOD(ROW()-2,20)+1,"00") -> 04 | C5: {=INDEX(Prompts_Txt_to_SQL!A:A, A5)&"-"&B5} -> P10-1-04 | D5: {=INDEX(Prompts_Txt_to_SQL!B:B, A5)} -> P10 | E5: {=INDEX(Prompts_Txt_to_SQL!C:C, A5)} -> 1 | F5: =CONCATENATE(D5,"-",E5) -> P10-1 | G5: =IFERROR(VLOOKUP(F5,Prompts_Txt_to_SQL!$A$2:$G$4,4,0),"") -> Đề xuất các chỉ số (KPI) chính để theo dõi hiệu quả bán hàng tổng thể dựa trên dataset. Chỉ liệt kê KPI, không cần biểu đồ.
A6: =INT((ROW()-2)/20)+2 -> 2 | B6: =TEXT(MOD(ROW()-2,20)+1,"00") -> 05 | C6: {=INDEX(Prompts_Txt_to_SQL!A:A, A6)&"-"&B6} -> P10-1-05 | D6: {=INDEX(Prompts_Txt_to_SQL!B:B, A6)} -> P10 | E6: {=INDEX(Prompts_Txt_to_SQL!C:C, A6)} -> 1 | F6: =CONCATENATE(D6,"-",E6) -> P10-1 | G6: =IFERROR(VLOOKUP(F6,Prompts_Txt_to_SQL!$A$2:$G$4,4,0),"") -> Đề xuất các chỉ số (KPI) chính để theo dõi hiệu quả bán hàng tổng thể dựa trên dataset. Chỉ liệt kê KPI, không cần biểu đồ.
A7: =INT((ROW()-2)/20)+2 -> 2 | B7: =TEXT(MOD(ROW()-2,20)+1,"00") -> 06 | C7: {=INDEX(Prompts_Txt_to_SQL!A:A, A7)&"-"&B7} -> P10-1-06 | D7: {=INDEX(Prompts_Txt_to_SQL!B:B, A7)} -> P10 | E7: {=INDEX(Prompts_Txt_to_SQL!C:C, A7)} -> 1 | F7: =CONCATENATE(D7,"-",E7) -> P10-1 | G7: =IFERROR(VLOOKUP(F7,Prompts_Txt_to_SQL!$A$2:$G$4,4,0),"") -> Đề xuất các chỉ số (KPI) chính để theo dõi hiệu quả bán hàng tổng thể dựa trên dataset. Chỉ liệt kê KPI, không cần biểu đồ.
A8: =INT((ROW()-2)/20)+2 -> 2 | B8: =TEXT(MOD(ROW()-2,20)+1,"00") -> 07 | C8: {=INDEX(Prompts_Txt_to_SQL!A:A, A8)&"-"&B8} -> P10-1-07 | D8: {=INDEX(Prompts_Txt_to_SQL!B:B, A8)} -> P10 | E8: {=INDEX(Prompts_Txt_to_SQL!C:C, A8)} -> 1 | F8: =CONCATENATE(D8,"-",E8) -> P10-1 | G8: =IFERROR(VLOOKUP(F8,Prompts_Txt_to_SQL!$A$2:$G$4,4,0),"") -> Đề xuất các chỉ số (KPI) chính để theo dõi hiệu quả bán hàng tổng thể dựa trên dataset. Chỉ liệt kê KPI, không cần biểu đồ.
A9: =INT((ROW()-2)/20)+2 -> 2 | B9: =TEXT(MOD(ROW()-2,20)+1,"00") -> 08 | C9: {=INDEX(Prompts_Txt_to_SQL!A:A, A9)&"-"&B9} -> P10-1-08 | D9: {=INDEX(Prompts_Txt_to_SQL!B:B, A9)} -> P10 | E9: {=INDEX(Prompts_Txt_to_SQL!C:C, A9)} -> 1 | F9: =CONCATENATE(D9,"-",E9) -> P10-1 | G9: =IFERROR(VLOOKUP(F9,Prompts_Txt_to_SQL!$A$2:$G$4,4,0),"") -> Đề xuất các chỉ số (KPI) chính để theo dõi hiệu quả bán hàng tổng thể dựa trên dataset. Chỉ liệt kê KPI, không cần biểu đồ.
A10: =INT((ROW()-2)/20)+2 -> 2 | B10: =TEXT(MOD(ROW()-2,20)+1,"00") -> 09 | C10: {=INDEX(Prompts_Txt_to_SQL!A:A, A10)&"-"&B10} -> P10-1-09 | D10: {=INDEX(Prompts_Txt_to_SQL!B:B, A10)} -> P10 | E10: {=INDEX(Prompts_Txt_to_SQL!C:C, A10)} -> 1 | F10: =CONCATENATE(D10,"-",E10) -> P10-1 | G10: =IFERROR(VLOOKUP(F10,Prompts_Txt_to_SQL!$A$2:$G$4,4,0),"") -> Đề xuất các chỉ số (KPI) chính để theo dõi hiệu quả bán hàng tổng thể dựa trên dataset. Chỉ liệt kê KPI, không cần biểu đồ.
A11: =INT((ROW()-2)/20)+2 -> 2 | B11: =TEXT(MOD(ROW()-2,20)+1,"00") -> 10 | C11: {=INDEX(Prompts_Txt_to_SQL!A:A, A11)&"-"&B11} -> P10-1-10 | D11: {=INDEX(Prompts_Txt_to_SQL!B:B, A11)} -> P10 | E11: {=INDEX(Prompts_Txt_to_SQL!C:C, A11)} -> 1 | F11: =CONCATENATE(D11,"-",E11) -> P10-1 | G11: =IFERROR(VLOOKUP(F11,Prompts_Txt_to_SQL!$A$2:$G$4,4,0),"") -> Đề xuất các chỉ số (KPI) chính để theo dõi hiệu quả bán hàng tổng thể dựa trên dataset. Chỉ liệt kê KPI, không cần biểu đồ.
A12: =INT((ROW()-2)/20)+2 -> 2 | B12: =TEXT(MOD(ROW()-2,20)+1,"00") -> 11 | C12: {=INDEX(Prompts_Txt_to_SQL!A:A, A12)&"-"&B12} -> P10-1-11 | D12: {=INDEX(Prompts_Txt_to_SQL!B:B, A12)} -> P10 | E12: {=INDEX(Prompts_Txt_to_SQL!C:C, A12)} -> 1 | F12: =CONCATENATE(D12,"-",E12) -> P10-1 | G12: =IFERROR(VLOOKUP(F12,Prompts_Txt_to_SQL!$A$2:$G$4,4,0),"") -> Đề xuất các chỉ số (KPI) chính để theo dõi hiệu quả bán hàng tổng thể dựa trên dataset. Chỉ liệt kê KPI, không cần biểu đồ.
A13: =INT((ROW()-2)/20)+2 -> 2 | B13: =TEXT(MOD(ROW()-2,20)+1,"00") -> 12 | C13: {=INDEX(Prompts_Txt_to_SQL!A:A, A13)&"-"&B13} -> P10-1-12 | D13: {=INDEX(Prompts_Txt_to_SQL!B:B, A13)} -> P10 | E13: {=INDEX(Prompts_Txt_to_SQL!C:C, A13)} -> 1 | F13: =CONCATENATE(D13,"-",E13) -> P10-1 | G13: =IFERROR(VLOOKUP(F13,Prompts_Txt_to_SQL!$A$2:$G$4,4,0),"") -> Đề xuất các chỉ số (KPI) chính để theo dõi hiệu quả bán hàng tổng thể dựa trên dataset. Chỉ liệt kê KPI, không cần biểu đồ.
... A601: =INT((ROW()-2)/20)+2 -> 31 | B601: =TEXT(MOD(ROW()-2,20)+1,"00") -> 20 | C601: {=INDEX(Prompts_Txt_to_SQL!A:A, A601)&"-"&B601} -> -20 | D601: {=INDEX(Prompts_Txt_to_SQL!B:B, A601)} -> 0 | E601: {=INDEX(Prompts_Txt_to_SQL!C:C, A601)} -> 0 | F601: =CONCATENATE(D601,"-",E601) -> 0-0 | G601: =IFERROR(VLOOKUP(F601,Prompts_Txt_to_SQL!$A$2:$G$4,4,0),"")

Sheet Types
